<?xml version="1.0" ?>
<!-- PuzzleBot differential drive -->
<robot name="puzzlebot" xmlns:xacro="http://www.ros.org/wiki/xacro">

	<!-- ================ URDF VARIABLES ================ -->
	<xacro:property name="PI" value="3.1415926535897931"/>
	
	<!-- ******   Base-Link   ****** -->
	<link name="map">
	</link>

	
	<!-- ================ CHASIS ================ -->
	<joint name="base_link_to_chassis" type="fixed">
		<parent link="map"/>
		<child link="base_link"/>
	</joint>

	<link name="base_link">
		<pose>0 0 0 0 0 0</pose>
		<visual>					
			<origin xyz="0 0 0" rpy="${PI/2} 0 ${PI/2}"/>
			<geometry>
				<mesh filename="file://$(find mini_challenge_1)/meshes/MCR2_1000_13_Chassis.stl"/>
			</geometry> 			
		</visual>

	</link>

	<!-- ================ RIGHT WHEEL ================ -->
	<joint name="base_to_right_w" type="continuous">
		<parent link="base_link" /> 
		<child link="right_wheel" />
		<origin xyz="0.05 -0.09 0.0" />
		<axis xyz="0 1 0" rpy="0 0 0" />
	</joint>

	<link name="right_wheel">
		<pose>0 0 0 0 0 0</pose>
		<visual>
			<origin xyz="0 0 0" rpy="-${PI/2} 0 0" />
			<geometry>	      
				<mesh filename="file://$(find mini_challenge_1)/meshes/MCR2_1000_1_1_Wheel_Coupler_2.stl"/>	    	
			</geometry>
		</visual>
	</link>

	<!-- ================ RIGHT WHEEL ================ -->
	<joint name="base_to_left_w" type="continuous">
		<parent link="base_link" /> 
		<child link="left_wheel" />
		<origin xyz="0.05 0.09 0.0" />
		<axis xyz="0 1 0" rpy="0 0 0" />
	</joint>
	
	<link name="left_wheel">
		<pose>0 0 0 0 0 0</pose>
		<visual>
			<origin xyz="0 0 0" rpy="${PI/2} 0 0" />
			<geometry>	      
				<mesh filename="file://$(find mini_challenge_1)/meshes/MCR2_1000_1_1_Wheel_Coupler_2.stl"/>	    	
			</geometry>
		</visual>
	</link>
	

<!---->
</robot>
